<?xml version="1.0"?><robot name="pepe">
	<link name="0">
		<visual>
			<geometry>
				<cylinder length="1.163314246530444" radius="0.9525115356694238"/>
			</geometry>
		</visual>
		<collision>
			<geometry>
				<cylinder length="1.163314246530444" radius="0.9525115356694238"/>
			</geometry>
		</collision>
		<inertial>
			<mass value="3.3157929778484196"/>
			<inertia ixx="0.03" iyy="0.03" izz="0.03" ixy="0" ixz="0" iyx="0"/>
		</inertial>
	</link>
	<link name="11">
		<visual>
			<geometry>
				<cylinder length="1.163314246530444" radius="0.9525115356694238"/>
			</geometry>
		</visual>
		<collision>
			<geometry>
				<cylinder length="1.163314246530444" radius="0.9525115356694238"/>
			</geometry>
		</collision>
		<inertial>
			<mass value="3.3157929778484196"/>
			<inertia ixx="0.03" iyy="0.03" izz="0.03" ixy="0" ixz="0" iyx="0"/>
		</inertial>
	</link>
	<link name="12">
		<visual>
			<geometry>
				<cylinder length="1.163314246530444" radius="0.9525115356694238"/>
			</geometry>
		</visual>
		<collision>
			<geometry>
				<cylinder length="1.163314246530444" radius="0.9525115356694238"/>
			</geometry>
		</collision>
		<inertial>
			<mass value="3.3157929778484196"/>
			<inertia ixx="0.03" iyy="0.03" izz="0.03" ixy="0" ixz="0" iyx="0"/>
		</inertial>
	</link>
	<joint name="11_to_0" type="revolute">
		<parent link="0"/>
		<child link="11"/>
		<axis xyz="1 0 0"/>
		<limit effort="1" upper="-3.1415" lower="3.1415" velocity="1"/>
		<origin rpy="10.972005849304917 0.6951093742314596 1.4270379558439286" xyz="0.7395836242400841 0.6250522943068633 0.9690711770830384"/>
	</joint>
	<joint name="12_to_0" type="revolute">
		<parent link="0"/>
		<child link="12"/>
		<axis xyz="1 0 0"/>
		<limit effort="1" upper="-3.1415" lower="3.1415" velocity="1"/>
		<origin rpy="16.458008773957374 0.6951093742314596 1.4270379558439286" xyz="0.7395836242400841 0.6250522943068633 0.9690711770830384"/>
	</joint>
</robot>
