<?xml version="1.0"?>
<robot name="roboCar">
    <link name="base_link">
        <visual>
            <geometry>
                <box size="1.5 1 1" />
            </geometry>
        </visual>
        <collision>
            <geometry>
                <box size="1.5 1 1" />
            </geometry>
        </collision>
        <inertial>
            <mass value="0.25"/>
            <inertia ixx="0.0003" iyy="0.0003" izz="0.0003" ixy="0" ixz="0" iyz="0"/>
        </inertial>
    </link>
    <link name="frwheel_link">
        <visual>
            <geometry>
                <cylinder length="0.6" radius="0.25"/>
            </geometry>
        </visual>
        <collision>
            <geometry>
                <cylinder length="0.6" radius="0.25"/>
            </geometry>
        </collision>
        <inertial>
            <mass value="0.25"/>
            <inertia ixx="0.0003" iyy="0.0003" izz="0.0003" ixy="0" ixz="0" iyz="0"/>
        </inertial>
    </link>
    <link name="rrwheel_link">
        <visual>
            <geometry>
                <cylinder length="0.6" radius="0.25"/>
            </geometry>
        </visual>
        <collision>
            <geometry>
                <cylinder length="0.6" radius="0.25"/>
            </geometry>
        </collision>
        <inertial>
            <mass value="0.25"/>
            <inertia ixx="0.0003" iyy="0.0003" izz="0.0003" ixy="0" ixz="0" iyz="0"/>
        </inertial>
    </link>
    <link name="rlw">
        <visual>
            <geometry>
                <cylinder length="0.6" radius="0.25"/>
            </geometry>
        </visual>
        <collision>
            <geometry>
                <cylinder length="0.6" radius="0.25"/>
            </geometry>
        </collision>
        <inertial>
            <mass value="0.25"/>
            <inertia ixx="0.0003" iyy="0.0003" izz="0.0003" ixy="0" ixz="0" iyz="0"/>
        </inertial>
    </link>
    <link name="flw">
        <visual>
            <geometry>
                <cylinder length="0.6" radius="0.25"/>
            </geometry>
        </visual>
        <collision>
            <geometry>
                <cylinder length="0.6" radius="0.25"/>
            </geometry>
        </collision>
        <inertial>
            <mass value="0.25"/>
            <inertia ixx="0.0003" iyy="0.0003" izz="0.0003" ixy="0" ixz="0" iyz="0"/>
        </inertial>
    </link>
    <joint name="base_to_sub" type="revolute">
        <parent link="base_link"/>
        <child link="frwheel_link"/>
        <axis xyz="0 0 1"/>
        <limit effort="10" upper="0" lower="10" velocity="1"/>
        <origin rpy="1.5 0 0" xyz="0.75 0.75 -0.5"/>
    </joint>
    <joint name="base_to_sub2" type="revolute">
        <parent link="base_link"/>
        <child link="rrwheel_link"/>
        <axis xyz="0 0 1"/>
        <limit effort="10" upper="0" lower="10" velocity="1"/>
        <origin rpy="1.5 0 0" xyz="-0.75 0.75 -0.5"/>
    </joint>
    <joint name="base_to_sub3" type="revolute">
        <parent link="base_link"/>
        <child link="rlw"/>
        <axis xyz="0 0 1"/>
        <limit effort="10" upper="0" lower="10" velocity="1"/>
        <origin rpy="1.5 0 0" xyz="-0.75 -0.75 -0.5"/>
    </joint>
    <joint name="base_to_sub4" type="revolute">
        <parent link="base_link"/>
        <child link="flw"/>
        <axis xyz="0 0 1"/>
        <limit effort="10" upper="0" lower="10" velocity="1"/>
        <origin rpy="1.5 0 0" xyz="0.75 -0.75 -0.5"/>
    </joint>
</robot>