<?xml version="1.0"?><robot name="pepe">
	<link name="0">
		<visual>
			<geometry>
				<cylinder length="0.29530951717184273" radius="0.19870015092907156"/>
			</geometry>
		</visual>
		<collision>
			<geometry>
				<cylinder length="0.29530951717184273" radius="0.19870015092907156"/>
			</geometry>
		</collision>
		<inertial>
			<mass value="0.03662888596785679"/>
			<inertia ixx="0.03" iyy="0.03" izz="0.03" ixy="0" ixz="0" iyx="0"/>
		</inertial>
	</link>
	<link name="11">
		<visual>
			<geometry>
				<cylinder length="0.2532065960551713" radius="0.5765985436187973"/>
			</geometry>
		</visual>
		<collision>
			<geometry>
				<cylinder length="0.2532065960551713" radius="0.5765985436187973"/>
			</geometry>
		</collision>
		<inertial>
			<mass value="0.26446729291381127"/>
			<inertia ixx="0.03" iyy="0.03" izz="0.03" ixy="0" ixz="0" iyx="0"/>
		</inertial>
	</link>
	<link name="22">
		<visual>
			<geometry>
				<cylinder length="1.0458677605157447" radius="0.48221080257613835"/>
			</geometry>
		</visual>
		<collision>
			<geometry>
				<cylinder length="1.0458677605157447" radius="0.48221080257613835"/>
			</geometry>
		</collision>
		<inertial>
			<mass value="0.7640125967359604"/>
			<inertia ixx="0.03" iyy="0.03" izz="0.03" ixy="0" ixz="0" iyx="0"/>
		</inertial>
	</link>
	<link name="23">
		<visual>
			<geometry>
				<cylinder length="1.0458677605157447" radius="0.48221080257613835"/>
			</geometry>
		</visual>
		<collision>
			<geometry>
				<cylinder length="1.0458677605157447" radius="0.48221080257613835"/>
			</geometry>
		</collision>
		<inertial>
			<mass value="0.7640125967359604"/>
			<inertia ixx="0.03" iyy="0.03" izz="0.03" ixy="0" ixz="0" iyx="0"/>
		</inertial>
	</link>
	<link name="14">
		<visual>
			<geometry>
				<cylinder length="0.2532065960551713" radius="0.5765985436187973"/>
			</geometry>
		</visual>
		<collision>
			<geometry>
				<cylinder length="0.2532065960551713" radius="0.5765985436187973"/>
			</geometry>
		</collision>
		<inertial>
			<mass value="0.26446729291381127"/>
			<inertia ixx="0.03" iyy="0.03" izz="0.03" ixy="0" ixz="0" iyx="0"/>
		</inertial>
	</link>
	<link name="25">
		<visual>
			<geometry>
				<cylinder length="1.0458677605157447" radius="0.48221080257613835"/>
			</geometry>
		</visual>
		<collision>
			<geometry>
				<cylinder length="1.0458677605157447" radius="0.48221080257613835"/>
			</geometry>
		</collision>
		<inertial>
			<mass value="0.7640125967359604"/>
			<inertia ixx="0.03" iyy="0.03" izz="0.03" ixy="0" ixz="0" iyx="0"/>
		</inertial>
	</link>
	<link name="26">
		<visual>
			<geometry>
				<cylinder length="1.0458677605157447" radius="0.48221080257613835"/>
			</geometry>
		</visual>
		<collision>
			<geometry>
				<cylinder length="1.0458677605157447" radius="0.48221080257613835"/>
			</geometry>
		</collision>
		<inertial>
			<mass value="0.7640125967359604"/>
			<inertia ixx="0.03" iyy="0.03" izz="0.03" ixy="0" ixz="0" iyx="0"/>
		</inertial>
	</link>
	<joint name="11_to_0" type="revolute">
		<parent link="0"/>
		<child link="11"/>
		<axis xyz="1 0 0"/>
		<limit effort="1" upper="-3.1415" lower="3.1415" velocity="1"/>
		<origin rpy="2.346661014776726 1.781064725250609 1.5965217213472793" xyz="0.9999 0.8346274683241105 0.9807371605957307"/>
	</joint>
	<joint name="22_to_11" type="revolute">
		<parent link="11"/>
		<child link="22"/>
		<axis xyz="1 0 0"/>
		<limit effort="1" upper="-3.1415" lower="3.1415" velocity="1"/>
		<origin rpy="0.6205493639575665 5.1512966192912 2.8832054081695433" xyz="0.1957885854865911 0.4421603294737 0.1263421961644826"/>
	</joint>
	<joint name="23_to_11" type="revolute">
		<parent link="11"/>
		<child link="23"/>
		<axis xyz="1 0 0"/>
		<limit effort="1" upper="-3.1415" lower="3.1415" velocity="1"/>
		<origin rpy="0.9308240459363498 5.1512966192912 2.8832054081695433" xyz="0.1957885854865911 0.4421603294737 0.1263421961644826"/>
	</joint>
	<joint name="14_to_0" type="revolute">
		<parent link="0"/>
		<child link="14"/>
		<axis xyz="1 0 0"/>
		<limit effort="1" upper="-3.1415" lower="3.1415" velocity="1"/>
		<origin rpy="3.519991522165089 1.781064725250609 1.5965217213472793" xyz="0.9999 0.8346274683241105 0.9807371605957307"/>
	</joint>
	<joint name="25_to_14" type="revolute">
		<parent link="14"/>
		<child link="25"/>
		<axis xyz="1 0 0"/>
		<limit effort="1" upper="-3.1415" lower="3.1415" velocity="1"/>
		<origin rpy="0.6205493639575665 5.1512966192912 2.8832054081695433" xyz="0.1957885854865911 0.4421603294737 0.1263421961644826"/>
	</joint>
	<joint name="26_to_14" type="revolute">
		<parent link="14"/>
		<child link="26"/>
		<axis xyz="1 0 0"/>
		<limit effort="1" upper="-3.1415" lower="3.1415" velocity="1"/>
		<origin rpy="0.9308240459363498 5.1512966192912 2.8832054081695433" xyz="0.1957885854865911 0.4421603294737 0.1263421961644826"/>
	</joint>
</robot>
